<?xml version="1.0" encoding="UTF-8"?>
<testsuite name="api.tests.test_ack_views.AckCountViewTestCase-20250630235212" tests="5" file="api/tests/test_ack_views.py" time="0.318" timestamp="2025-06-30T23:52:12" failures="0" errors="1" skipped="0">
	<testcase classname="api.tests.test_ack_views.AckCountViewTestCase" name="test_ackcount_detail_invalid_rule_id" time="0.007" timestamp="2025-06-30T23:52:12" file="advisor/api/tests/test_ack_views.py" line="452"/>
	<testcase classname="api.tests.test_ack_views.AckCountViewTestCase" name="test_ackcount_endpoint_access_fails_for_non_internal_user" time="0.005" timestamp="2025-06-30T23:52:12" file="advisor/api/tests/test_ack_views.py" line="469"/>
	<testcase classname="api.tests.test_ack_views.AckCountViewTestCase" name="test_ackcount_list" time="0.004" timestamp="2025-06-30T23:52:12" file="advisor/api/tests/test_ack_views.py" line="400"/>
	<testcase classname="api.tests.test_ack_views.AckCountViewTestCase" name="test_add_deleting_acks_to_modify_ack_counts" time="0.021" timestamp="2025-06-30T23:52:12" file="advisor/api/tests/test_ack_views.py" line="426"/>
	<testcase classname="api.tests.test_ack_views.AckCountViewTestCase" name="test_ackcount_detail" time="0.281" timestamp="2025-06-30T23:52:12" file="advisor/api/tests/test_ack_views.py" line="415">
		<error type="FieldError" message="Cannot resolve keyword 'rule' into field. Choices are: ack, ack_count, active, category, category_id, created_at, currentreport, deleted_at, description, generic, hostack, id, impact, impact_id, likelihood, more_info, node_id, pathway, pathway_id, publish_date, reason, reboot_required, resolution, rule_id, rulerating, ruleset, ruleset_id, satmaintenanceaction, summary, tags, total_risk, updated_at"><![CDATA[Traceback (most recent call last):
  File "/home/pwayper/Code/insights/advisor-backend/api/advisor/api/tests/test_ack_views.py", line 417, in test_ackcount_detail
    response = self.client.get(
               ^^^^^^^^^^^^^^^^
  File "/home/pwayper/.local/share/virtualenvs/advisor-backend-A3tAKjzl/lib/python3.12/site-packages/django/test/client.py", line 1124, in get
    response = super().get(
               ^^^^^^^^^^^^
  File "/home/pwayper/.local/share/virtualenvs/advisor-backend-A3tAKjzl/lib/python3.12/site-packages/django/test/client.py", line 475, in get
    return self.generic(
           ^^^^^^^^^^^^^
  File "/home/pwayper/.local/share/virtualenvs/advisor-backend-A3tAKjzl/lib/python3.12/site-packages/django/test/client.py", line 671, in generic
    return self.request(**r)
           ^^^^^^^^^^^^^^^^^
  File "/home/pwayper/.local/share/virtualenvs/advisor-backend-A3tAKjzl/lib/python3.12/site-packages/django/test/client.py", line 1087, in request
    self.check_exception(response)
  File "/home/pwayper/.local/share/virtualenvs/advisor-backend-A3tAKjzl/lib/python3.12/site-packages/django/test/client.py", line 802, in check_exception
    raise exc_value
  File "/home/pwayper/.local/share/virtualenvs/advisor-backend-A3tAKjzl/lib/python3.12/site-packages/django/core/handlers/exception.py", line 55, in inner
    response = get_response(request)
               ^^^^^^^^^^^^^^^^^^^^^
  File "/home/pwayper/.local/share/virtualenvs/advisor-backend-A3tAKjzl/lib/python3.12/site-packages/django/core/handlers/base.py", line 197, in _get_response
    response = wrapped_callback(request, *callback_args, **callback_kwargs)
               ^^^^^^^^^^^^^^^^^^^^^^^^^^^^^^^^^^^^^^^^^^^^^^^^^^^^^^^^^^^^
  File "/home/pwayper/.local/share/virtualenvs/advisor-backend-A3tAKjzl/lib/python3.12/site-packages/django/views/decorators/csrf.py", line 65, in _view_wrapper
    return view_func(request, *args, **kwargs)
           ^^^^^^^^^^^^^^^^^^^^^^^^^^^^^^^^^^^
  File "/home/pwayper/.local/share/virtualenvs/advisor-backend-A3tAKjzl/lib/python3.12/site-packages/rest_framework/viewsets.py", line 125, in view
    return self.dispatch(request, *args, **kwargs)
           ^^^^^^^^^^^^^^^^^^^^^^^^^^^^^^^^^^^^^^^
  File "/home/pwayper/.local/share/virtualenvs/advisor-backend-A3tAKjzl/lib/python3.12/site-packages/rest_framework/views.py", line 515, in dispatch
    response = self.handle_exception(exc)
               ^^^^^^^^^^^^^^^^^^^^^^^^^^
  File "/home/pwayper/.local/share/virtualenvs/advisor-backend-A3tAKjzl/lib/python3.12/site-packages/rest_framework/views.py", line 475, in handle_exception
    self.raise_uncaught_exception(exc)
  File "/home/pwayper/.local/share/virtualenvs/advisor-backend-A3tAKjzl/lib/python3.12/site-packages/rest_framework/views.py", line 486, in raise_uncaught_exception
    raise exc
  File "/home/pwayper/.local/share/virtualenvs/advisor-backend-A3tAKjzl/lib/python3.12/site-packages/rest_framework/views.py", line 512, in dispatch
    response = handler(request, *args, **kwargs)
               ^^^^^^^^^^^^^^^^^^^^^^^^^^^^^^^^^
  File "/home/pwayper/Code/insights/advisor-backend/api/advisor/api/views/acks.py", line 214, in retrieve
    rule_ack_count = self.queryset.get(rule=rule)
                     ^^^^^^^^^^^^^^^^^^^^^^^^^^^^
  File "/home/pwayper/.local/share/virtualenvs/advisor-backend-A3tAKjzl/lib/python3.12/site-packages/django/db/models/query.py", line 619, in get
    clone = self._chain() if self.query.combinator else self.filter(*args, **kwargs)
                                                        ^^^^^^^^^^^^^^^^^^^^^^^^^^^^
  File "/home/pwayper/.local/share/virtualenvs/advisor-backend-A3tAKjzl/lib/python3.12/site-packages/django/db/models/query.py", line 1493, in filter
    return self._filter_or_exclude(False, args, kwargs)
           ^^^^^^^^^^^^^^^^^^^^^^^^^^^^^^^^^^^^^^^^^^^^
  File "/home/pwayper/.local/share/virtualenvs/advisor-backend-A3tAKjzl/lib/python3.12/site-packages/django/db/models/query.py", line 1511, in _filter_or_exclude
    clone._filter_or_exclude_inplace(negate, args, kwargs)
  File "/home/pwayper/.local/share/virtualenvs/advisor-backend-A3tAKjzl/lib/python3.12/site-packages/django/db/models/query.py", line 1518, in _filter_or_exclude_inplace
    self._query.add_q(Q(*args, **kwargs))
  File "/home/pwayper/.local/share/virtualenvs/advisor-backend-A3tAKjzl/lib/python3.12/site-packages/django/db/models/sql/query.py", line 1646, in add_q
    clause, _ = self._add_q(q_object, can_reuse)
                ^^^^^^^^^^^^^^^^^^^^^^^^^^^^^^^^
  File "/home/pwayper/.local/share/virtualenvs/advisor-backend-A3tAKjzl/lib/python3.12/site-packages/django/db/models/sql/query.py", line 1678, in _add_q
    child_clause, needed_inner = self.build_filter(
                                 ^^^^^^^^^^^^^^^^^^
  File "/home/pwayper/.local/share/virtualenvs/advisor-backend-A3tAKjzl/lib/python3.12/site-packages/django/db/models/sql/query.py", line 1526, in build_filter
    lookups, parts, reffed_expression = self.solve_lookup_type(arg, summarize)
                                        ^^^^^^^^^^^^^^^^^^^^^^^^^^^^^^^^^^^^^^
  File "/home/pwayper/.local/share/virtualenvs/advisor-backend-A3tAKjzl/lib/python3.12/site-packages/django/db/models/sql/query.py", line 1333, in solve_lookup_type
    _, field, _, lookup_parts = self.names_to_path(lookup_splitted, self.get_meta())
                                ^^^^^^^^^^^^^^^^^^^^^^^^^^^^^^^^^^^^^^^^^^^^^^^^^^^^
  File "/home/pwayper/.local/share/virtualenvs/advisor-backend-A3tAKjzl/lib/python3.12/site-packages/django/db/models/sql/query.py", line 1805, in names_to_path
    raise FieldError(
django.core.exceptions.FieldError: Cannot resolve keyword 'rule' into field. Choices are: ack, ack_count, active, category, category_id, created_at, currentreport, deleted_at, description, generic, hostack, id, impact, impact_id, likelihood, more_info, node_id, pathway, pathway_id, publish_date, reason, reboot_required, resolution, rule_id, rulerating, ruleset, ruleset_id, satmaintenanceaction, summary, tags, total_risk, updated_at
]]></error>
	</testcase>
</testsuite>
