<?xml version="1.0" encoding="UTF-8"?>
<testsuite name="api.tests.test_ack_views.AckCountViewTestCase-20250630235907" tests="5" file="api/tests/test_ack_views.py" time="0.310" timestamp="2025-06-30T23:59:07" failures="1" errors="1" skipped="0">
	<testcase classname="api.tests.test_ack_views.AckCountViewTestCase" name="test_ackcount_detail" time="0.277" timestamp="2025-06-30T23:59:07" file="advisor/api/tests/test_ack_views.py" line="415"/>
	<testcase classname="api.tests.test_ack_views.AckCountViewTestCase" name="test_ackcount_detail_invalid_rule_id" time="0.006" timestamp="2025-06-30T23:59:07" file="advisor/api/tests/test_ack_views.py" line="452"/>
	<testcase classname="api.tests.test_ack_views.AckCountViewTestCase" name="test_ackcount_endpoint_access_fails_for_non_internal_user" time="0.005" timestamp="2025-06-30T23:59:07" file="advisor/api/tests/test_ack_views.py" line="469"/>
	<testcase classname="api.tests.test_ack_views.AckCountViewTestCase" name="test_ackcount_list" time="0.006" timestamp="2025-06-30T23:59:07" file="advisor/api/tests/test_ack_views.py" line="400">
		<failure type="AssertionError" message="{'meta': {'count': 3}, 'links': {'first': '/r/insights/platform/insights/v1/ackcount/?limit=10&amp;offset=0', 'next': '/r/insights/platform/insights/v1/ackcount/?limit=10&amp;offset=0', 'previous': '/r/insights/platform/insights/v1/ackcount/?limit=10&amp;offset=0', 'last': '/r/insights/platform/insights/v1/ackcount/?limit=10&amp;offset=0'}, 'data': [{'rule_id': 'test|Acked_rule', 'ack_count': 2}, {'rule_id': 'test|Active_rule', 'ack_count': 0}, {'rule_id': 'test|Second_rule', 'ack_count': 1}]} is not an instance of &lt;class 'list'&gt;"><![CDATA[Traceback (most recent call last):
  File "/home/pwayper/Code/insights/advisor-backend/api/advisor/api/tests/test_ack_views.py", line 409, in test_ackcount_list
    self.assertIsInstance(ackcount_list, list)
AssertionError: {'meta': {'count': 3}, 'links': {'first': '/r/insights/platform/insights/v1/ackcount/?limit=10&offset=0', 'next': '/r/insights/platform/insights/v1/ackcount/?limit=10&offset=0', 'previous': '/r/insights/platform/insights/v1/ackcount/?limit=10&offset=0', 'last': '/r/insights/platform/insights/v1/ackcount/?limit=10&offset=0'}, 'data': [{'rule_id': 'test|Acked_rule', 'ack_count': 2}, {'rule_id': 'test|Active_rule', 'ack_count': 0}, {'rule_id': 'test|Second_rule', 'ack_count': 1}]} is not an instance of <class 'list'>
]]></failure>
	</testcase>
	<testcase classname="api.tests.test_ack_views.AckCountViewTestCase" name="test_add_deleting_acks_to_modify_ack_counts" time="0.017" timestamp="2025-06-30T23:59:07" file="advisor/api/tests/test_ack_views.py" line="426">
		<error type="TypeError" message="unhashable type: 'dict'"><![CDATA[Traceback (most recent call last):
  File "/home/pwayper/Code/insights/advisor-backend/api/advisor/api/tests/test_ack_views.py", line 438, in test_add_deleting_acks_to_modify_ack_counts
    self.assertIn(self.ack_table['acked_rule'], ackcount_list)
  File "/usr/lib64/python3.12/unittest/case.py", line 1149, in assertIn
    if member not in container:
       ^^^^^^^^^^^^^^^^^^^^^^^
TypeError: unhashable type: 'dict'
]]></error>
	</testcase>
</testsuite>
